<?xml version="1.0" ?>
<robot name="rhacobot" xmlns:xacro="http://www.ros.org/wiki/xacro">

<xacro:include filename="$(find rhacobot_description)/urdf/materials.xacro" />
<xacro:include filename="$(find rhacobot_description)/urdf/rhacobot.trans" />
<xacro:include filename="$(find rhacobot_description)/urdf/rhacobot.gazebo" />
<link name="base_link">
  <inertial>
    <origin xyz="0.0030 0.00019 -0.0106" rpy="0 0 0"/>
    <mass value="12"/>
    <inertia ixx="0.51769" iyy="0.558751" izz="0.677145" ixy="-0.000945" iyz="-0.000551" ixz="-0.047"/>
  </inertial>
  <visual>
    <origin xyz="0 0 0" rpy="0 0 0"/>
    <geometry>
      <mesh filename="file://$(find rhacobot_description)/meshes/chassis.stl" scale="0.001 0.001 0.001"/>
    </geometry>
    <material name="silver"/>
  </visual>
  <collision>
    <origin xyz="0 0 0" rpy="0 0 0"/>
    <geometry>
      <mesh filename="file://$(find rhacobot_description)/meshes/chassis.stl" scale="0.001 0.001 0.001"/>
    </geometry>
  </collision>
</link>

<link name="wheel_left">
  <inertial>
    <origin xyz="0 0.050 0" rpy="0 0 0"/>
    <mass value="1"/>
    <inertia ixx="0.116536" iyy="0.230663" izz="0.116536" ixy="0" iyz="0" ixz="0"/>
  </inertial>
  <visual>
    <origin xyz="0 -0.1645 0.0" rpy="0 0 0"/>
    <geometry>
      <mesh filename="file://$(find rhacobot_description)/meshes/wheel_left.stl" scale="0.001 0.001 0.001"/>
    </geometry>
    <material name="silver"/>
  </visual>
  <collision>
    <origin xyz="0 -0.1645 0.0" rpy="0 0 0"/>
    <geometry>
      <mesh filename="file://$(find rhacobot_description)/meshes/wheel_left.stl" scale="0.001 0.001 0.001"/>
    </geometry>
  </collision>
</link>

<link name="wheel_right">
  <inertial>
    <origin xyz="0 0.050 0" rpy="0 0 0"/>
    <mass value="1"/>
    <inertia ixx="0.116536" iyy="0.230663" izz="0.116536" ixy="0" iyz="0" ixz="0"/>
  </inertial>
  <visual>
    <origin xyz="0 0.1645 0" rpy="0 0 0"/>
    <geometry>
      <mesh filename="file://$(find rhacobot_description)/meshes/wheel_right.stl" scale="0.001 0.001 0.001"/>
    </geometry>
    <material name="silver"/>
  </visual>
  <collision>
    <origin xyz="0 0.1645 0" rpy="0 0 0"/>
    <geometry>
      <mesh filename="file://$(find rhacobot_description)/meshes/wheel_right.stl" scale="0.001 0.001 0.001"/>
    </geometry>
  </collision>
</link>

<link name="tail_joint_a">
  <inertial>
    <origin xyz="0.040 -0.0015 0.0726" rpy="0 0 0"/>
    <mass value="0.5"/>
    <inertia ixx="0.00587" iyy="0.003137" izz="0.004066" ixy="-8.7e-05" iyz="1.4e-05" ixz="-0.000113"/>
  </inertial>
  <visual>
    <origin xyz="0.185 0.0 0.0335" rpy="0 0 0"/>
    <geometry>
      <mesh filename="file://$(find rhacobot_description)/meshes/tail_joint_a.stl" scale="0.001 0.001 0.001"/>
    </geometry>
    <material name="silver"/>
  </visual>
  <collision>
    <origin xyz="0.185 0.0 0.0335" rpy="0 0 0"/>
    <geometry>
      <mesh filename="file://$(find rhacobot_description)/meshes/tail_joint_a.stl" scale="0.001 0.001 0.001"/>
    </geometry>
  </collision>
</link>

<link name="tail_joint_b">
  <inertial>
    <origin xyz="-0.05621904802267569 0.07590565725710019 -1.5844244384763395e-06" rpy="0 0 0"/>
    <mass value="10.477562961596828"/>
    <inertia ixx="0.020039" iyy="0.085189" izz="0.093057" ixy="0.000861" iyz="0" ixz="3e-06"/>
  </inertial>
  <visual>
    <origin xyz="0.185 0.0745 -0.0455" rpy="0 0 0"/>
    <geometry>
      <mesh filename="file://$(find rhacobot_description)/meshes/tail_joint_b.stl" scale="0.001 0.001 0.001"/>
    </geometry>
    <material name="silver"/>
  </visual>
  <collision>
    <origin xyz="0.185 0.0745 -0.0455" rpy="0 0 0"/>
    <geometry>
      <mesh filename="file://$(find rhacobot_description)/meshes/tail_joint_b.stl" scale="0.001 0.001 0.001"/>
    </geometry>
  </collision>
</link>

<link name="tail_joint_c">
  <inertial>
    <origin xyz="-0.10172534531154215 0.05545870393255971 0.005701632728430342" rpy="0 0 0"/>
    <mass value="3.887618406244789"/>
    <inertia ixx="0.003221" iyy="0.03439" izz="0.034039" ixy="-0.00117" iyz="6.6e-05" ixz="0.00276"/>
  </inertial>
  <visual>
    <origin xyz="0.435 0.0525 -0.045508" rpy="0 0 0"/>
    <geometry>
      <mesh filename="file://$(find rhacobot_description)/meshes/tail_joint_c.stl" scale="0.001 0.001 0.001"/>
    </geometry>
    <material name="silver"/>
  </visual>
  <collision>
    <origin xyz="0.435 0.0525 -0.045508" rpy="0 0 0"/>
    <geometry>
      <mesh filename="file://$(find rhacobot_description)/meshes/tail_joint_c.stl" scale="0.001 0.001 0.001"/>
    </geometry>
  </collision>
</link>

<link name="wheel_tail">
  <inertial>
    <origin xyz="-4.802598116970813e-07 -0.015999999880835572 -2.4656365327224705e-07" rpy="0 0 0"/>
    <mass value="7.002535975446206"/>
    <inertia ixx="0.022076" iyy="0.018567" izz="0.022076" ixy="0.0" iyz="0" ixz="0"/>
  </inertial>
  <visual>
    <origin xyz="0.692256 -0.016 -0.07512" rpy="0 0 0"/>
    <geometry>
      <mesh filename="file://$(find rhacobot_description)/meshes/wheel_tail.stl" scale="0.001 0.001 0.001"/>
    </geometry>
    <material name="silver"/>
  </visual>
  <collision>
    <origin xyz="0.692256 -0.016 -0.07512" rpy="0 0 0"/>
    <geometry>
      <mesh filename="file://$(find rhacobot_description)/meshes/wheel_tail.stl" scale="0.001 0.001 0.001"/>
    </geometry>
  </collision>
</link>

<joint name="R�volution 1" type="continuous">
  <origin xyz="0.0 0.1645 0.0" rpy="0 0 0"/>
  <parent link="base_link"/>
  <child link="wheel_left_1"/>
  <axis xyz="0.0 1.0 0.0"/>
</joint>

<joint name="R�volution 2" type="continuous">
  <origin xyz="0.0 -0.1645 0.0" rpy="0 0 0"/>
  <parent link="base_link"/>
  <child link="wheel_right_1"/>
  <axis xyz="0 -1.0 0.0"/>
</joint>

<joint name="R�volution 3" type="continuous">
  <origin xyz="-0.185 0.0 -0.0335" rpy="0 0 0"/>
  <parent link="base_link"/>
  <child link="tail_joint_a_1"/>
  <axis xyz="0.0 0.0 1.0"/>
</joint>

<joint name="R�volution 4" type="continuous">
  <origin xyz="0.0 -0.0745 0.079" rpy="0 0 0"/>
  <parent link="tail_joint_a_1"/>
  <child link="tail_joint_b_1"/>
  <axis xyz="0.0 -1.0 0"/>
</joint>

<joint name="R�volution 5" type="continuous">
  <origin xyz="-0.25 0.022 8e-06" rpy="0 0 0"/>
  <parent link="tail_joint_b_1"/>
  <child link="tail_joint_c_1"/>
  <axis xyz="0.0 -1.0 0"/>
</joint>

<joint name="R�volution 6" type="continuous">
  <origin xyz="-0.257256 0.0685 0.029612" rpy="0 0 0"/>
  <parent link="tail_joint_c_1"/>
  <child link="wheel_tail_1"/>
  <axis xyz="0 -1.0 0.0"/>
</joint>

</robot>
