<?xml version="1.0"?>
<robot xmlns:xacro="http://www.ros.org/wiki/xacro">

    <xacro:property name="shoulder_radius" value="0.05" />
    <xacro:property name="shoulder_length" value="0.162" />
    <xacro:property name="arm_radius" value="0.08" />
    <xacro:property name="arm_length" value="0.25" /> 
    <xacro:property name="tail_wheel_radius" value="0.075" />
    <xacro:property name="tail_wheel_length" value="0.22" />


    <link name="tail_base_link">
        <visual>
            <origin xyz="0 0 0" rpy="0 0 0" />
            <geometry>
                <cylinder radius="0.02" length="0.01" />
                </geometry>
            <material name="red" />
        </visual>
        <collision>
            <geometry>
                <cylinder radius="0.02" length="0.01" />
            </geometry>
            <origin xyz="0 0 0.079" rpy="0 0 0" />
        </collision>
        <xacro:cylinder_inertia m="0.0001" r="0.02" h="0.01"
            xyz="0 0 0" rpy="0 0 0" />
    </link>

    <joint name="body_tail_base_joint" type="fixed">
        <parent link="body_link" />
        <child link="tail_base_link" />
        <origin xyz="-0.185 0 -0.0335" rpy="0 0 0" />
    </joint>

    <link name="tail_shoulder_link">
        <visual>
            <origin xyz="0 0 0" rpy="0 0 0" />
            <geometry>
                <mesh filename="file://$(find rhacobot_description)/meshes/tail_joint_a.stl"
                    scale="0.001 0.001 0.001" />
                </geometry>
            <material name="orange" />
        </visual>
        <collision>
            <geometry>
                <cylinder radius="${shoulder_radius}" length="${shoulder_length}" />
            </geometry>
            <origin xyz="0 0 0.079" rpy="${pi / 2.0} 0 0" />
        </collision>
        <xacro:cylinder_inertia m="1.0" r="${gazebo_drift_factor * shoulder_radius}" h="${gazebo_drift_factor * shoulder_length}"
            xyz="0 0 0" rpy="${pi / 2.0} 0 0" />
    </link>
    
    <joint name="tail_base_shoulder_joint" type="revolute">
        <parent link="tail_base_link" />
        <child link="tail_shoulder_link" />
        <origin xyz="0 0 0" rpy="0 0 ${pi}" />
        <limit effort="100" velocity="100" lower="-${pi/4}" upper="${pi/4}" />
        <axis xyz="0 0 1" />
    </joint>

    <link name="tail_arm_link">
        <visual>
            <origin xyz="0 0 0" rpy="0 0 0" />
            <geometry>
                <mesh filename="file://$(find rhacobot_description)/meshes/tail_joint_b.stl"
                    scale="0.001 0.001 0.001" />
            </geometry>
            <material name="blue" />
        </visual>
        <collision>    <!-- tail_joint_c macro -->
            <origin xyz="0 0 0" rpy="0 0 0" />
            <geometry>
                <mesh filename="file://$(find rhacobot_description)/meshes/tail_joint_b.stl"
                    scale="0.001 0.001 0.001" />
            </geometry>
        </collision>
        <xacro:cylinder_inertia m="1.0" r="${gazebo_drift_factor * arm_radius}" h="${gazebo_drift_factor * arm_length}"
            xyz="0 0 0" rpy="0 ${pi / 2.0} 0" />
    </link>

    <joint name="shoulder_arm_joint" type="revolute">
        <parent link="tail_shoulder_link" />
        <child link="tail_arm_link" />
        <origin xyz="0 0 0.079" rpy="0 ${pi} ${pi}" />
        <limit effort="100" velocity="100" lower="${-pi/2 + pi}" upper="${pi/6 + pi}" />
        <axis xyz="0 1 0" />
    </joint>

    <link name="tail_forearm_link">
        <visual>
            <origin xyz="0 0 0" rpy="0 0 0" />
            <geometry>
                <mesh filename="file://$(find rhacobot_description)/meshes/tail_joint_c.stl"
                    scale="0.001 0.001 0.001" />
            </geometry>
            <material name="blue" />
        </visual>
        <collision>
            <origin xyz="0 0 0" rpy="0 0 0" />
            <geometry>        
                <mesh filename="file://$(find rhacobot_description)/meshes/tail_joint_c.stl"
                    scale="0.001 0.001 0.001" />
            </geometry>
        </collision>
        <xacro:cylinder_inertia m="1.0" r="${gazebo_drift_factor * arm_radius}" h="${gazebo_drift_factor * arm_length}"
            xyz="0 0 0" rpy="0 ${pi / 2.0} 0" />
    </link>

    <joint name="arm_forearm_joint" type="revolute">
        <parent link="tail_arm_link" />
        <child link="tail_forearm_link" />
        <origin xyz="0.25 0 0" rpy="0 0 0" />
        <limit effort="100" velocity="100" lower="-${pi/4}" upper="${pi/1.4}" />
        <axis xyz="0 1 0" />
    </joint> 

    <link name="tail_wheel_link">
        <visual>
            <origin xyz="0 0 0" rpy="0 0 0" />
            <geometry>
                <mesh filename="file://$(find rhacobot_description)/meshes/tail_wheel.stl"
                    scale="0.001 0.001 0.001" />
            </geometry>
            <material name="green" />
        </visual>
        <collision>
            <geometry>
                <sphere radius="${tail_wheel_radius}"/>
            </geometry>
            <origin xyz="0 0 0" rpy="${pi / 2.0} 0 0" />
        </collision>
        <xacro:cylinder_inertia m="1.0" r="${gazebo_drift_factor * tail_wheel_radius}" h="${gazebo_drift_factor * tail_wheel_length}"
            xyz="0 0 0" rpy="${pi / 2.0} 0 0" />
    </link>

    <joint name="forearm_wheel_joint" type="fixed">
        <parent link="tail_forearm_link" />
        <child link="tail_wheel_link" />
        <origin xyz="0.257256 0 0.029611" rpy="0 0 0" />
    </joint>

</robot>